{
 "cells": [
  {
   "cell_type": "code",
   "execution_count": 1,
   "metadata": {},
   "outputs": [],
   "source": [
    "import tensorflow as tf\n",
    "import xarray as xr\n",
    "from dataGenerator import make_generator\n",
    "import numpy as np\n",
    "import glob\n",
    "import os"
   ]
  },
  {
   "cell_type": "code",
   "execution_count": 2,
   "metadata": {
    "scrolled": false
   },
   "outputs": [
    {
     "name": "stdout",
     "output_type": "stream",
     "text": [
      "mag_data_2000.nc\n"
     ]
    },
    {
     "ename": "InvalidArgumentError",
     "evalue": "TypeError: Cannot convert input [<xarray.DataArray 'Date_UTC' ()>\narray('2000-01-01T02:21:00.000000000', dtype='datetime64[ns]')\nCoordinates:\n    Date_UTC  datetime64[ns] 2000-01-01T02:21:00] of type <class 'xarray.core.dataarray.DataArray'> to Timestamp\nTraceback (most recent call last):\n\n  File \"C:\\Users\\Greg\\AppData\\Local\\conda\\conda\\envs\\py36\\lib\\site-packages\\pandas\\core\\indexes\\base.py\", line 3078, in get_loc\n    return self._engine.get_loc(key)\n\n  File \"pandas\\_libs\\index.pyx\", line 419, in pandas._libs.index.DatetimeEngine.get_loc\n\n  File \"pandas\\_libs\\index.pyx\", line 455, in pandas._libs.index.DatetimeEngine.get_loc\n\n  File \"pandas\\_libs\\hashtable_class_helper.pxi\", line 958, in pandas._libs.hashtable.Int64HashTable.get_item\n\n  File \"pandas\\_libs\\hashtable_class_helper.pxi\", line 964, in pandas._libs.hashtable.Int64HashTable.get_item\n\nKeyError: 946693260000000000\n\n\nDuring handling of the above exception, another exception occurred:\n\n\nTraceback (most recent call last):\n\n  File \"C:\\Users\\Greg\\AppData\\Local\\conda\\conda\\envs\\py36\\lib\\site-packages\\pandas\\core\\indexes\\datetimes.py\", line 1613, in get_loc\n    return Index.get_loc(self, key, method, tolerance)\n\n  File \"C:\\Users\\Greg\\AppData\\Local\\conda\\conda\\envs\\py36\\lib\\site-packages\\pandas\\core\\indexes\\base.py\", line 3080, in get_loc\n    return self._engine.get_loc(self._maybe_cast_indexer(key))\n\n  File \"pandas\\_libs\\index.pyx\", line 419, in pandas._libs.index.DatetimeEngine.get_loc\n\n  File \"pandas\\_libs\\index.pyx\", line 455, in pandas._libs.index.DatetimeEngine.get_loc\n\n  File \"pandas\\_libs\\hashtable_class_helper.pxi\", line 958, in pandas._libs.hashtable.Int64HashTable.get_item\n\n  File \"pandas\\_libs\\hashtable_class_helper.pxi\", line 964, in pandas._libs.hashtable.Int64HashTable.get_item\n\nKeyError: 946693260000000000\n\n\nDuring handling of the above exception, another exception occurred:\n\n\nTraceback (most recent call last):\n\n  File \"C:\\Users\\Greg\\AppData\\Local\\conda\\conda\\envs\\py36\\lib\\site-packages\\tensorflow\\python\\ops\\script_ops.py\", line 206, in __call__\n    ret = func(*args)\n\n  File \"C:\\Users\\Greg\\AppData\\Local\\conda\\conda\\envs\\py36\\lib\\site-packages\\tensorflow\\python\\data\\ops\\dataset_ops.py\", line 451, in generator_py_func\n    values = next(generator_state.get_iterator(iterator_id))\n\n  File \"C:\\Users\\Greg\\code\\space-physics-machine-learning\\dataGenerator.py\", line 85, in gen\n    target_chunk = ss[int_beg:int_end]\n\n  File \"C:\\Users\\Greg\\AppData\\Local\\conda\\conda\\envs\\py36\\lib\\site-packages\\pandas\\core\\frame.py\", line 2676, in __getitem__\n    indexer = convert_to_index_sliceable(self, key)\n\n  File \"C:\\Users\\Greg\\AppData\\Local\\conda\\conda\\envs\\py36\\lib\\site-packages\\pandas\\core\\indexing.py\", line 2326, in convert_to_index_sliceable\n    return idx._convert_slice_indexer(key, kind='getitem')\n\n  File \"C:\\Users\\Greg\\AppData\\Local\\conda\\conda\\envs\\py36\\lib\\site-packages\\pandas\\core\\indexes\\base.py\", line 1751, in _convert_slice_indexer\n    indexer = self.slice_indexer(start, stop, step, kind=kind)\n\n  File \"C:\\Users\\Greg\\AppData\\Local\\conda\\conda\\envs\\py36\\lib\\site-packages\\pandas\\core\\indexes\\datetimes.py\", line 1706, in slice_indexer\n    return Index.slice_indexer(self, start, end, step, kind=kind)\n\n  File \"C:\\Users\\Greg\\AppData\\Local\\conda\\conda\\envs\\py36\\lib\\site-packages\\pandas\\core\\indexes\\base.py\", line 4107, in slice_indexer\n    kind=kind)\n\n  File \"C:\\Users\\Greg\\AppData\\Local\\conda\\conda\\envs\\py36\\lib\\site-packages\\pandas\\core\\indexes\\base.py\", line 4308, in slice_locs\n    start_slice = self.get_slice_bound(start, 'left', kind)\n\n  File \"C:\\Users\\Greg\\AppData\\Local\\conda\\conda\\envs\\py36\\lib\\site-packages\\pandas\\core\\indexes\\base.py\", line 4238, in get_slice_bound\n    slc = self._get_loc_only_exact_matches(label)\n\n  File \"C:\\Users\\Greg\\AppData\\Local\\conda\\conda\\envs\\py36\\lib\\site-packages\\pandas\\core\\indexes\\base.py\", line 4207, in _get_loc_only_exact_matches\n    return self.get_loc(key)\n\n  File \"C:\\Users\\Greg\\AppData\\Local\\conda\\conda\\envs\\py36\\lib\\site-packages\\pandas\\core\\indexes\\datetimes.py\", line 1621, in get_loc\n    stamp = Timestamp(key, tz=self.tz)\n\n  File \"pandas\\_libs\\tslibs\\timestamps.pyx\", line 644, in pandas._libs.tslibs.timestamps.Timestamp.__new__\n\n  File \"pandas\\_libs\\tslibs\\conversion.pyx\", line 309, in pandas._libs.tslibs.conversion.convert_to_tsobject\n\nTypeError: Cannot convert input [<xarray.DataArray 'Date_UTC' ()>\narray('2000-01-01T02:21:00.000000000', dtype='datetime64[ns]')\nCoordinates:\n    Date_UTC  datetime64[ns] 2000-01-01T02:21:00] of type <class 'xarray.core.dataarray.DataArray'> to Timestamp\n\n\n\t [[{{node PyFunc}} = PyFunc[Tin=[DT_INT64], Tout=[DT_FLOAT, DT_FLOAT, DT_FLOAT, DT_FLOAT], token=\"pyfunc_1\"](arg0)]]\n\t [[node IteratorGetNext (defined at <ipython-input-2-80d27669b9e4>:32)  = IteratorGetNext[output_shapes=[[?,?,128,3], [?,?,3], [?,1], [?,1], [?,3]], output_types=[DT_FLOAT, DT_FLOAT, DT_FLOAT, DT_FLOAT, DT_FLOAT], _device=\"/job:localhost/replica:0/task:0/device:CPU:0\"](IteratorV2)]]",
     "traceback": [
      "\u001b[1;31m---------------------------------------------------------------------------\u001b[0m",
      "\u001b[1;31mInvalidArgumentError\u001b[0m                      Traceback (most recent call last)",
      "\u001b[1;32m~\\AppData\\Local\\conda\\conda\\envs\\py36\\lib\\site-packages\\tensorflow\\python\\client\\session.py\u001b[0m in \u001b[0;36m_do_call\u001b[1;34m(self, fn, *args)\u001b[0m\n\u001b[0;32m   1333\u001b[0m     \u001b[1;32mtry\u001b[0m\u001b[1;33m:\u001b[0m\u001b[1;33m\u001b[0m\u001b[1;33m\u001b[0m\u001b[0m\n\u001b[1;32m-> 1334\u001b[1;33m       \u001b[1;32mreturn\u001b[0m \u001b[0mfn\u001b[0m\u001b[1;33m(\u001b[0m\u001b[1;33m*\u001b[0m\u001b[0margs\u001b[0m\u001b[1;33m)\u001b[0m\u001b[1;33m\u001b[0m\u001b[1;33m\u001b[0m\u001b[0m\n\u001b[0m\u001b[0;32m   1335\u001b[0m     \u001b[1;32mexcept\u001b[0m \u001b[0merrors\u001b[0m\u001b[1;33m.\u001b[0m\u001b[0mOpError\u001b[0m \u001b[1;32mas\u001b[0m \u001b[0me\u001b[0m\u001b[1;33m:\u001b[0m\u001b[1;33m\u001b[0m\u001b[1;33m\u001b[0m\u001b[0m\n",
      "\u001b[1;32m~\\AppData\\Local\\conda\\conda\\envs\\py36\\lib\\site-packages\\tensorflow\\python\\client\\session.py\u001b[0m in \u001b[0;36m_run_fn\u001b[1;34m(feed_dict, fetch_list, target_list, options, run_metadata)\u001b[0m\n\u001b[0;32m   1318\u001b[0m       return self._call_tf_sessionrun(\n\u001b[1;32m-> 1319\u001b[1;33m           options, feed_dict, fetch_list, target_list, run_metadata)\n\u001b[0m\u001b[0;32m   1320\u001b[0m \u001b[1;33m\u001b[0m\u001b[0m\n",
      "\u001b[1;32m~\\AppData\\Local\\conda\\conda\\envs\\py36\\lib\\site-packages\\tensorflow\\python\\client\\session.py\u001b[0m in \u001b[0;36m_call_tf_sessionrun\u001b[1;34m(self, options, feed_dict, fetch_list, target_list, run_metadata)\u001b[0m\n\u001b[0;32m   1406\u001b[0m         \u001b[0mself\u001b[0m\u001b[1;33m.\u001b[0m\u001b[0m_session\u001b[0m\u001b[1;33m,\u001b[0m \u001b[0moptions\u001b[0m\u001b[1;33m,\u001b[0m \u001b[0mfeed_dict\u001b[0m\u001b[1;33m,\u001b[0m \u001b[0mfetch_list\u001b[0m\u001b[1;33m,\u001b[0m \u001b[0mtarget_list\u001b[0m\u001b[1;33m,\u001b[0m\u001b[1;33m\u001b[0m\u001b[1;33m\u001b[0m\u001b[0m\n\u001b[1;32m-> 1407\u001b[1;33m         run_metadata)\n\u001b[0m\u001b[0;32m   1408\u001b[0m \u001b[1;33m\u001b[0m\u001b[0m\n",
      "\u001b[1;31mInvalidArgumentError\u001b[0m: TypeError: Cannot convert input [<xarray.DataArray 'Date_UTC' ()>\narray('2000-01-01T02:21:00.000000000', dtype='datetime64[ns]')\nCoordinates:\n    Date_UTC  datetime64[ns] 2000-01-01T02:21:00] of type <class 'xarray.core.dataarray.DataArray'> to Timestamp\nTraceback (most recent call last):\n\n  File \"C:\\Users\\Greg\\AppData\\Local\\conda\\conda\\envs\\py36\\lib\\site-packages\\pandas\\core\\indexes\\base.py\", line 3078, in get_loc\n    return self._engine.get_loc(key)\n\n  File \"pandas\\_libs\\index.pyx\", line 419, in pandas._libs.index.DatetimeEngine.get_loc\n\n  File \"pandas\\_libs\\index.pyx\", line 455, in pandas._libs.index.DatetimeEngine.get_loc\n\n  File \"pandas\\_libs\\hashtable_class_helper.pxi\", line 958, in pandas._libs.hashtable.Int64HashTable.get_item\n\n  File \"pandas\\_libs\\hashtable_class_helper.pxi\", line 964, in pandas._libs.hashtable.Int64HashTable.get_item\n\nKeyError: 946693260000000000\n\n\nDuring handling of the above exception, another exception occurred:\n\n\nTraceback (most recent call last):\n\n  File \"C:\\Users\\Greg\\AppData\\Local\\conda\\conda\\envs\\py36\\lib\\site-packages\\pandas\\core\\indexes\\datetimes.py\", line 1613, in get_loc\n    return Index.get_loc(self, key, method, tolerance)\n\n  File \"C:\\Users\\Greg\\AppData\\Local\\conda\\conda\\envs\\py36\\lib\\site-packages\\pandas\\core\\indexes\\base.py\", line 3080, in get_loc\n    return self._engine.get_loc(self._maybe_cast_indexer(key))\n\n  File \"pandas\\_libs\\index.pyx\", line 419, in pandas._libs.index.DatetimeEngine.get_loc\n\n  File \"pandas\\_libs\\index.pyx\", line 455, in pandas._libs.index.DatetimeEngine.get_loc\n\n  File \"pandas\\_libs\\hashtable_class_helper.pxi\", line 958, in pandas._libs.hashtable.Int64HashTable.get_item\n\n  File \"pandas\\_libs\\hashtable_class_helper.pxi\", line 964, in pandas._libs.hashtable.Int64HashTable.get_item\n\nKeyError: 946693260000000000\n\n\nDuring handling of the above exception, another exception occurred:\n\n\nTraceback (most recent call last):\n\n  File \"C:\\Users\\Greg\\AppData\\Local\\conda\\conda\\envs\\py36\\lib\\site-packages\\tensorflow\\python\\ops\\script_ops.py\", line 206, in __call__\n    ret = func(*args)\n\n  File \"C:\\Users\\Greg\\AppData\\Local\\conda\\conda\\envs\\py36\\lib\\site-packages\\tensorflow\\python\\data\\ops\\dataset_ops.py\", line 451, in generator_py_func\n    values = next(generator_state.get_iterator(iterator_id))\n\n  File \"C:\\Users\\Greg\\code\\space-physics-machine-learning\\dataGenerator.py\", line 85, in gen\n    target_chunk = ss[int_beg:int_end]\n\n  File \"C:\\Users\\Greg\\AppData\\Local\\conda\\conda\\envs\\py36\\lib\\site-packages\\pandas\\core\\frame.py\", line 2676, in __getitem__\n    indexer = convert_to_index_sliceable(self, key)\n\n  File \"C:\\Users\\Greg\\AppData\\Local\\conda\\conda\\envs\\py36\\lib\\site-packages\\pandas\\core\\indexing.py\", line 2326, in convert_to_index_sliceable\n    return idx._convert_slice_indexer(key, kind='getitem')\n\n  File \"C:\\Users\\Greg\\AppData\\Local\\conda\\conda\\envs\\py36\\lib\\site-packages\\pandas\\core\\indexes\\base.py\", line 1751, in _convert_slice_indexer\n    indexer = self.slice_indexer(start, stop, step, kind=kind)\n\n  File \"C:\\Users\\Greg\\AppData\\Local\\conda\\conda\\envs\\py36\\lib\\site-packages\\pandas\\core\\indexes\\datetimes.py\", line 1706, in slice_indexer\n    return Index.slice_indexer(self, start, end, step, kind=kind)\n\n  File \"C:\\Users\\Greg\\AppData\\Local\\conda\\conda\\envs\\py36\\lib\\site-packages\\pandas\\core\\indexes\\base.py\", line 4107, in slice_indexer\n    kind=kind)\n\n  File \"C:\\Users\\Greg\\AppData\\Local\\conda\\conda\\envs\\py36\\lib\\site-packages\\pandas\\core\\indexes\\base.py\", line 4308, in slice_locs\n    start_slice = self.get_slice_bound(start, 'left', kind)\n\n  File \"C:\\Users\\Greg\\AppData\\Local\\conda\\conda\\envs\\py36\\lib\\site-packages\\pandas\\core\\indexes\\base.py\", line 4238, in get_slice_bound\n    slc = self._get_loc_only_exact_matches(label)\n\n  File \"C:\\Users\\Greg\\AppData\\Local\\conda\\conda\\envs\\py36\\lib\\site-packages\\pandas\\core\\indexes\\base.py\", line 4207, in _get_loc_only_exact_matches\n    return self.get_loc(key)\n\n  File \"C:\\Users\\Greg\\AppData\\Local\\conda\\conda\\envs\\py36\\lib\\site-packages\\pandas\\core\\indexes\\datetimes.py\", line 1621, in get_loc\n    stamp = Timestamp(key, tz=self.tz)\n\n  File \"pandas\\_libs\\tslibs\\timestamps.pyx\", line 644, in pandas._libs.tslibs.timestamps.Timestamp.__new__\n\n  File \"pandas\\_libs\\tslibs\\conversion.pyx\", line 309, in pandas._libs.tslibs.conversion.convert_to_tsobject\n\nTypeError: Cannot convert input [<xarray.DataArray 'Date_UTC' ()>\narray('2000-01-01T02:21:00.000000000', dtype='datetime64[ns]')\nCoordinates:\n    Date_UTC  datetime64[ns] 2000-01-01T02:21:00] of type <class 'xarray.core.dataarray.DataArray'> to Timestamp\n\n\n\t [[{{node PyFunc}} = PyFunc[Tin=[DT_INT64], Tout=[DT_FLOAT, DT_FLOAT, DT_FLOAT, DT_FLOAT], token=\"pyfunc_1\"](arg0)]]\n\t [[{{node IteratorGetNext}} = IteratorGetNext[output_shapes=[[?,?,128,3], [?,?,3], [?,1], [?,1], [?,3]], output_types=[DT_FLOAT, DT_FLOAT, DT_FLOAT, DT_FLOAT, DT_FLOAT], _device=\"/job:localhost/replica:0/task:0/device:CPU:0\"](IteratorV2)]]",
      "\nDuring handling of the above exception, another exception occurred:\n",
      "\u001b[1;31mInvalidArgumentError\u001b[0m                      Traceback (most recent call last)",
      "\u001b[1;32m<ipython-input-2-80d27669b9e4>\u001b[0m in \u001b[0;36m<module>\u001b[1;34m\u001b[0m\n\u001b[0;32m     34\u001b[0m \u001b[0msess\u001b[0m \u001b[1;33m=\u001b[0m \u001b[0mtf\u001b[0m\u001b[1;33m.\u001b[0m\u001b[0mSession\u001b[0m\u001b[1;33m(\u001b[0m\u001b[1;33m)\u001b[0m\u001b[1;33m\u001b[0m\u001b[1;33m\u001b[0m\u001b[0m\n\u001b[0;32m     35\u001b[0m \u001b[0msess\u001b[0m\u001b[1;33m.\u001b[0m\u001b[0mrun\u001b[0m\u001b[1;33m(\u001b[0m\u001b[0mdata_iter\u001b[0m\u001b[1;33m.\u001b[0m\u001b[0minitializer\u001b[0m\u001b[1;33m)\u001b[0m\u001b[1;33m\u001b[0m\u001b[1;33m\u001b[0m\u001b[0m\n\u001b[1;32m---> 36\u001b[1;33m \u001b[0msess\u001b[0m\u001b[1;33m.\u001b[0m\u001b[0mrun\u001b[0m\u001b[1;33m(\u001b[0m\u001b[0mmag\u001b[0m\u001b[1;33m)\u001b[0m\u001b[1;33m\u001b[0m\u001b[1;33m\u001b[0m\u001b[0m\n\u001b[0m",
      "\u001b[1;32m~\\AppData\\Local\\conda\\conda\\envs\\py36\\lib\\site-packages\\tensorflow\\python\\client\\session.py\u001b[0m in \u001b[0;36mrun\u001b[1;34m(self, fetches, feed_dict, options, run_metadata)\u001b[0m\n\u001b[0;32m    927\u001b[0m     \u001b[1;32mtry\u001b[0m\u001b[1;33m:\u001b[0m\u001b[1;33m\u001b[0m\u001b[1;33m\u001b[0m\u001b[0m\n\u001b[0;32m    928\u001b[0m       result = self._run(None, fetches, feed_dict, options_ptr,\n\u001b[1;32m--> 929\u001b[1;33m                          run_metadata_ptr)\n\u001b[0m\u001b[0;32m    930\u001b[0m       \u001b[1;32mif\u001b[0m \u001b[0mrun_metadata\u001b[0m\u001b[1;33m:\u001b[0m\u001b[1;33m\u001b[0m\u001b[1;33m\u001b[0m\u001b[0m\n\u001b[0;32m    931\u001b[0m         \u001b[0mproto_data\u001b[0m \u001b[1;33m=\u001b[0m \u001b[0mtf_session\u001b[0m\u001b[1;33m.\u001b[0m\u001b[0mTF_GetBuffer\u001b[0m\u001b[1;33m(\u001b[0m\u001b[0mrun_metadata_ptr\u001b[0m\u001b[1;33m)\u001b[0m\u001b[1;33m\u001b[0m\u001b[1;33m\u001b[0m\u001b[0m\n",
      "\u001b[1;32m~\\AppData\\Local\\conda\\conda\\envs\\py36\\lib\\site-packages\\tensorflow\\python\\client\\session.py\u001b[0m in \u001b[0;36m_run\u001b[1;34m(self, handle, fetches, feed_dict, options, run_metadata)\u001b[0m\n\u001b[0;32m   1150\u001b[0m     \u001b[1;32mif\u001b[0m \u001b[0mfinal_fetches\u001b[0m \u001b[1;32mor\u001b[0m \u001b[0mfinal_targets\u001b[0m \u001b[1;32mor\u001b[0m \u001b[1;33m(\u001b[0m\u001b[0mhandle\u001b[0m \u001b[1;32mand\u001b[0m \u001b[0mfeed_dict_tensor\u001b[0m\u001b[1;33m)\u001b[0m\u001b[1;33m:\u001b[0m\u001b[1;33m\u001b[0m\u001b[1;33m\u001b[0m\u001b[0m\n\u001b[0;32m   1151\u001b[0m       results = self._do_run(handle, final_targets, final_fetches,\n\u001b[1;32m-> 1152\u001b[1;33m                              feed_dict_tensor, options, run_metadata)\n\u001b[0m\u001b[0;32m   1153\u001b[0m     \u001b[1;32melse\u001b[0m\u001b[1;33m:\u001b[0m\u001b[1;33m\u001b[0m\u001b[1;33m\u001b[0m\u001b[0m\n\u001b[0;32m   1154\u001b[0m       \u001b[0mresults\u001b[0m \u001b[1;33m=\u001b[0m \u001b[1;33m[\u001b[0m\u001b[1;33m]\u001b[0m\u001b[1;33m\u001b[0m\u001b[1;33m\u001b[0m\u001b[0m\n",
      "\u001b[1;32m~\\AppData\\Local\\conda\\conda\\envs\\py36\\lib\\site-packages\\tensorflow\\python\\client\\session.py\u001b[0m in \u001b[0;36m_do_run\u001b[1;34m(self, handle, target_list, fetch_list, feed_dict, options, run_metadata)\u001b[0m\n\u001b[0;32m   1326\u001b[0m     \u001b[1;32mif\u001b[0m \u001b[0mhandle\u001b[0m \u001b[1;32mis\u001b[0m \u001b[1;32mNone\u001b[0m\u001b[1;33m:\u001b[0m\u001b[1;33m\u001b[0m\u001b[1;33m\u001b[0m\u001b[0m\n\u001b[0;32m   1327\u001b[0m       return self._do_call(_run_fn, feeds, fetches, targets, options,\n\u001b[1;32m-> 1328\u001b[1;33m                            run_metadata)\n\u001b[0m\u001b[0;32m   1329\u001b[0m     \u001b[1;32melse\u001b[0m\u001b[1;33m:\u001b[0m\u001b[1;33m\u001b[0m\u001b[1;33m\u001b[0m\u001b[0m\n\u001b[0;32m   1330\u001b[0m       \u001b[1;32mreturn\u001b[0m \u001b[0mself\u001b[0m\u001b[1;33m.\u001b[0m\u001b[0m_do_call\u001b[0m\u001b[1;33m(\u001b[0m\u001b[0m_prun_fn\u001b[0m\u001b[1;33m,\u001b[0m \u001b[0mhandle\u001b[0m\u001b[1;33m,\u001b[0m \u001b[0mfeeds\u001b[0m\u001b[1;33m,\u001b[0m \u001b[0mfetches\u001b[0m\u001b[1;33m)\u001b[0m\u001b[1;33m\u001b[0m\u001b[1;33m\u001b[0m\u001b[0m\n",
      "\u001b[1;32m~\\AppData\\Local\\conda\\conda\\envs\\py36\\lib\\site-packages\\tensorflow\\python\\client\\session.py\u001b[0m in \u001b[0;36m_do_call\u001b[1;34m(self, fn, *args)\u001b[0m\n\u001b[0;32m   1346\u001b[0m           \u001b[1;32mpass\u001b[0m\u001b[1;33m\u001b[0m\u001b[1;33m\u001b[0m\u001b[0m\n\u001b[0;32m   1347\u001b[0m       \u001b[0mmessage\u001b[0m \u001b[1;33m=\u001b[0m \u001b[0merror_interpolation\u001b[0m\u001b[1;33m.\u001b[0m\u001b[0minterpolate\u001b[0m\u001b[1;33m(\u001b[0m\u001b[0mmessage\u001b[0m\u001b[1;33m,\u001b[0m \u001b[0mself\u001b[0m\u001b[1;33m.\u001b[0m\u001b[0m_graph\u001b[0m\u001b[1;33m)\u001b[0m\u001b[1;33m\u001b[0m\u001b[1;33m\u001b[0m\u001b[0m\n\u001b[1;32m-> 1348\u001b[1;33m       \u001b[1;32mraise\u001b[0m \u001b[0mtype\u001b[0m\u001b[1;33m(\u001b[0m\u001b[0me\u001b[0m\u001b[1;33m)\u001b[0m\u001b[1;33m(\u001b[0m\u001b[0mnode_def\u001b[0m\u001b[1;33m,\u001b[0m \u001b[0mop\u001b[0m\u001b[1;33m,\u001b[0m \u001b[0mmessage\u001b[0m\u001b[1;33m)\u001b[0m\u001b[1;33m\u001b[0m\u001b[1;33m\u001b[0m\u001b[0m\n\u001b[0m\u001b[0;32m   1349\u001b[0m \u001b[1;33m\u001b[0m\u001b[0m\n\u001b[0;32m   1350\u001b[0m   \u001b[1;32mdef\u001b[0m \u001b[0m_extend_graph\u001b[0m\u001b[1;33m(\u001b[0m\u001b[0mself\u001b[0m\u001b[1;33m)\u001b[0m\u001b[1;33m:\u001b[0m\u001b[1;33m\u001b[0m\u001b[1;33m\u001b[0m\u001b[0m\n",
      "\u001b[1;31mInvalidArgumentError\u001b[0m: TypeError: Cannot convert input [<xarray.DataArray 'Date_UTC' ()>\narray('2000-01-01T02:21:00.000000000', dtype='datetime64[ns]')\nCoordinates:\n    Date_UTC  datetime64[ns] 2000-01-01T02:21:00] of type <class 'xarray.core.dataarray.DataArray'> to Timestamp\nTraceback (most recent call last):\n\n  File \"C:\\Users\\Greg\\AppData\\Local\\conda\\conda\\envs\\py36\\lib\\site-packages\\pandas\\core\\indexes\\base.py\", line 3078, in get_loc\n    return self._engine.get_loc(key)\n\n  File \"pandas\\_libs\\index.pyx\", line 419, in pandas._libs.index.DatetimeEngine.get_loc\n\n  File \"pandas\\_libs\\index.pyx\", line 455, in pandas._libs.index.DatetimeEngine.get_loc\n\n  File \"pandas\\_libs\\hashtable_class_helper.pxi\", line 958, in pandas._libs.hashtable.Int64HashTable.get_item\n\n  File \"pandas\\_libs\\hashtable_class_helper.pxi\", line 964, in pandas._libs.hashtable.Int64HashTable.get_item\n\nKeyError: 946693260000000000\n\n\nDuring handling of the above exception, another exception occurred:\n\n\nTraceback (most recent call last):\n\n  File \"C:\\Users\\Greg\\AppData\\Local\\conda\\conda\\envs\\py36\\lib\\site-packages\\pandas\\core\\indexes\\datetimes.py\", line 1613, in get_loc\n    return Index.get_loc(self, key, method, tolerance)\n\n  File \"C:\\Users\\Greg\\AppData\\Local\\conda\\conda\\envs\\py36\\lib\\site-packages\\pandas\\core\\indexes\\base.py\", line 3080, in get_loc\n    return self._engine.get_loc(self._maybe_cast_indexer(key))\n\n  File \"pandas\\_libs\\index.pyx\", line 419, in pandas._libs.index.DatetimeEngine.get_loc\n\n  File \"pandas\\_libs\\index.pyx\", line 455, in pandas._libs.index.DatetimeEngine.get_loc\n\n  File \"pandas\\_libs\\hashtable_class_helper.pxi\", line 958, in pandas._libs.hashtable.Int64HashTable.get_item\n\n  File \"pandas\\_libs\\hashtable_class_helper.pxi\", line 964, in pandas._libs.hashtable.Int64HashTable.get_item\n\nKeyError: 946693260000000000\n\n\nDuring handling of the above exception, another exception occurred:\n\n\nTraceback (most recent call last):\n\n  File \"C:\\Users\\Greg\\AppData\\Local\\conda\\conda\\envs\\py36\\lib\\site-packages\\tensorflow\\python\\ops\\script_ops.py\", line 206, in __call__\n    ret = func(*args)\n\n  File \"C:\\Users\\Greg\\AppData\\Local\\conda\\conda\\envs\\py36\\lib\\site-packages\\tensorflow\\python\\data\\ops\\dataset_ops.py\", line 451, in generator_py_func\n    values = next(generator_state.get_iterator(iterator_id))\n\n  File \"C:\\Users\\Greg\\code\\space-physics-machine-learning\\dataGenerator.py\", line 85, in gen\n    target_chunk = ss[int_beg:int_end]\n\n  File \"C:\\Users\\Greg\\AppData\\Local\\conda\\conda\\envs\\py36\\lib\\site-packages\\pandas\\core\\frame.py\", line 2676, in __getitem__\n    indexer = convert_to_index_sliceable(self, key)\n\n  File \"C:\\Users\\Greg\\AppData\\Local\\conda\\conda\\envs\\py36\\lib\\site-packages\\pandas\\core\\indexing.py\", line 2326, in convert_to_index_sliceable\n    return idx._convert_slice_indexer(key, kind='getitem')\n\n  File \"C:\\Users\\Greg\\AppData\\Local\\conda\\conda\\envs\\py36\\lib\\site-packages\\pandas\\core\\indexes\\base.py\", line 1751, in _convert_slice_indexer\n    indexer = self.slice_indexer(start, stop, step, kind=kind)\n\n  File \"C:\\Users\\Greg\\AppData\\Local\\conda\\conda\\envs\\py36\\lib\\site-packages\\pandas\\core\\indexes\\datetimes.py\", line 1706, in slice_indexer\n    return Index.slice_indexer(self, start, end, step, kind=kind)\n\n  File \"C:\\Users\\Greg\\AppData\\Local\\conda\\conda\\envs\\py36\\lib\\site-packages\\pandas\\core\\indexes\\base.py\", line 4107, in slice_indexer\n    kind=kind)\n\n  File \"C:\\Users\\Greg\\AppData\\Local\\conda\\conda\\envs\\py36\\lib\\site-packages\\pandas\\core\\indexes\\base.py\", line 4308, in slice_locs\n    start_slice = self.get_slice_bound(start, 'left', kind)\n\n  File \"C:\\Users\\Greg\\AppData\\Local\\conda\\conda\\envs\\py36\\lib\\site-packages\\pandas\\core\\indexes\\base.py\", line 4238, in get_slice_bound\n    slc = self._get_loc_only_exact_matches(label)\n\n  File \"C:\\Users\\Greg\\AppData\\Local\\conda\\conda\\envs\\py36\\lib\\site-packages\\pandas\\core\\indexes\\base.py\", line 4207, in _get_loc_only_exact_matches\n    return self.get_loc(key)\n\n  File \"C:\\Users\\Greg\\AppData\\Local\\conda\\conda\\envs\\py36\\lib\\site-packages\\pandas\\core\\indexes\\datetimes.py\", line 1621, in get_loc\n    stamp = Timestamp(key, tz=self.tz)\n\n  File \"pandas\\_libs\\tslibs\\timestamps.pyx\", line 644, in pandas._libs.tslibs.timestamps.Timestamp.__new__\n\n  File \"pandas\\_libs\\tslibs\\conversion.pyx\", line 309, in pandas._libs.tslibs.conversion.convert_to_tsobject\n\nTypeError: Cannot convert input [<xarray.DataArray 'Date_UTC' ()>\narray('2000-01-01T02:21:00.000000000', dtype='datetime64[ns]')\nCoordinates:\n    Date_UTC  datetime64[ns] 2000-01-01T02:21:00] of type <class 'xarray.core.dataarray.DataArray'> to Timestamp\n\n\n\t [[{{node PyFunc}} = PyFunc[Tin=[DT_INT64], Tout=[DT_FLOAT, DT_FLOAT, DT_FLOAT, DT_FLOAT], token=\"pyfunc_1\"](arg0)]]\n\t [[node IteratorGetNext (defined at <ipython-input-2-80d27669b9e4>:32)  = IteratorGetNext[output_shapes=[[?,?,128,3], [?,?,3], [?,1], [?,1], [?,3]], output_types=[DT_FLOAT, DT_FLOAT, DT_FLOAT, DT_FLOAT, DT_FLOAT], _device=\"/job:localhost/replica:0/task:0/device:CPU:0\"](IteratorV2)]]"
     ],
     "output_type": "error"
    }
   ],
   "source": [
    "os.chdir(\"data\")\n",
    "\n",
    "mag_files = glob.glob(\"mag_data_*.nc\")\n",
    "ss_file = \"substorms_2000_2018.csv\"\n",
    "stats_file = \"statistics.npz\"\n",
    "data_interval = 128\n",
    "prediction_interval = 64\n",
    "channels = 3\n",
    "\n",
    "BATCHSIZE = 1\n",
    "\n",
    "gen, par = make_generator(mag_files, ss_file, stats_file, data_interval, prediction_interval)\n",
    "\n",
    "dataset = tf.data.Dataset.from_generator(gen,\n",
    "                                         output_types = (tf.float32, tf.float32, tf.float32, tf.float32),\n",
    "                                         output_shapes = (tf.TensorShape([None, data_interval, 6]),\n",
    "                                                          tf.TensorShape([1]),\n",
    "                                                          tf.TensorShape([1]),\n",
    "                                                          tf.TensorShape([3]))\n",
    "                                        )\n",
    "\n",
    "dataset = dataset.map(par)\n",
    "\n",
    "dataset = dataset.padded_batch(BATCHSIZE, (tf.TensorShape([None, data_interval, channels]),\n",
    "                                           tf.TensorShape([None, 3]), \n",
    "                                           tf.TensorShape([1]), \n",
    "                                           tf.TensorShape([1]),\n",
    "                                           tf.TensorShape([3]))).repeat()\n",
    "\n",
    "data_iter = dataset.make_initializable_iterator()\n",
    "\n",
    "mag, st_loc, occ, ss_t, ss_loc = data_iter.get_next()\n",
    "\n",
    "sess = tf.Session()\n",
    "sess.run(data_iter.initializer)\n",
    "sess.run(mag)"
   ]
  }
 ],
 "metadata": {
  "kernelspec": {
   "display_name": "Python 3",
   "language": "python",
   "name": "python3"
  },
  "language_info": {
   "codemirror_mode": {
    "name": "ipython",
    "version": 3
   },
   "file_extension": ".py",
   "mimetype": "text/x-python",
   "name": "python",
   "nbconvert_exporter": "python",
   "pygments_lexer": "ipython3",
   "version": "3.6.7"
  }
 },
 "nbformat": 4,
 "nbformat_minor": 2
}
